File: SampleUTMdata.csv
Time,Extension,Load,Strain 1,,,
(s),(mm),(N),(mm/mm),,,
0,0,0.11,0,,,
0.2,0.0235,332.66,0.00003,,,
0.4,0.04681,511.76,0.00004,,,
0.6,0.07016,660.33,0.00005,,,
0.8,0.09342,790.63,0.00006,,,
1,0.11682,904.85,0.00007,,,
1.2,0.14032,1009.24,0.00008,,,
1.4,0.16348,1099.10,0.00009,,,
1.6,0.18698,1181.82,0.00009,,,
1.8,0.21008,1256.13,0.0001,,,
2,0.23369,1328.50,0.00011,,,
2.2,0.25684,1395.89,0.00012,,,
2.4,0.2802,1457.01,0.00013,,,
2.6,0.3035,1519.44,0.00013,,,
2.8,0.32685,1578.53,0.00013,,,
3,0.35046,1643.12,0.00014,,,
3.2,0.37346,1704.72,0.00015,,,
3.4,0.39696,1769.09,0.00015,,,
3.6,0.42007,1838.60,0.00016,,,
3.8,0.44362,1912.20,0.00017,,,
4,0.46687,1991.38,0.00018,,,
4.2,0.49023,2071.51,0.00018,,,
4.4,0.51353,2156.20,0.00019,,,
4.6,0.53684,2243.83,0.0002,,,
4.8,0.56044,2337.51,0.00021,,,
5,0.58344,2430.15,0.00022,,,
5.2,0.607,2524.30,0.00023,,,
5.4,0.63005,2621.47,0.00024,,,
5.6,0.65371,2721.82,0.00025,,,
5.8,0.67686,2824.49,0.00026,,,
6,0.70021,2926.69,0.00027,,,
6.2,0.72357,3032.01,0.00028,,,
6.4,0.74692,3137.87,0.00029,,,
6.6,0.77037,3248.30,0.00031,,,
6.8,0.79348,3358.75,0.00032,,,
7,0.81688,3468.67,0.00033,,,
7.2,0.84013,3582.25,0.00035,,,
7.4,0.86354,3698.37,0.00036,,,
7.6,0.88699,3820.63,0.00037,,,
7.8,0.91014,3940.66,0.00038,,,
8,0.93365,4067.65,0.0004,,,
8.2,0.95685,4192.44,0.00042,,,
8.4,0.98036,4324.47,0.00043,,,
8.6,1.00351,4459.19,0.00044,,,
8.8,1.02691,4592.46,0.00046,,,
9,1.05017,4732.77,0.00047,,,
9.2,1.07347,4869.16,0.00049,,,
9.4,1.09698,5016.44,0.0005,,,
9.6,1.12018,5160.89,0.00052,,,
9.8,1.14363,5311.78,0.00054,,,
10,1.16679,5460.23,0.00055,,,
10.2,1.19029,5614.78,0.00057,,,
10.4,1.21344,5772.66,0.00059,,,
10.6,1.23685,5929.03,0.00061,,,
10.8,1.26015,6091.73,0.00063,,,
11,1.2835,6250.79,0.00065,,,
11.2,1.30696,6417.99,0.00067,,,
11.4,1.33016,6584.77,0.00069,,,
11.6,1.35362,6754.99,0.00071,,,
11.8,1.37672,6927.55,0.00073,,,
12,1.40022,7098.52,0.00075,,,
12.2,1.42353,7278.21,0.00078,,,
12.4,1.44683,7451.49,0.00079,,,
12.6,1.47018,7635.17,0.00082,,,
12.8,1.49349,7815.14,0.00084,,,
13,1.51699,7997.05,0.00086,,,
13.2,1.54014,8183.75,0.00089,,,
13.4,1.56355,8370.36,0.00091,,,
13.6,1.58675,8563.96,0.00094,,,
13.8,1.61021,8757.05,0.00096,,,
14,1.63356,8953.31,0.00098,,,
14.2,1.65681,9146.94,0.00101,,,
14.4,1.68017,9346.56,0.00103,,,
14.6,1.70352,9546.50,0.00106,,,
14.8,1.72692,9748.33,0.00109,,,
15,1.75018,9948.59,0.00112,,,
15.2,1.77358,10150.33,0.00114,,,
15.4,1.79663,10359.03,0.00117,,,
15.6,1.82029,10563.93,0.00119,,,
15.8,1.84349,10774.16,0.00122,,,
16,1.86685,10978.18,0.00125,,,
16.2,1.8902,11189.94,0.00129,,,
16.4,1.91355,11404.36,0.00132,,,
16.6,1.93696,11616.40,0.00135,,,
16.8,1.96016,11835.73,0.00139,,,
17,1.98357,12042.93,0.00142,,,
17.2,2.00677,12262.83,0.00145,,,
17.4,2.03022,12479.95,0.00149,,,
17.6,2.05368,12704.57,0.00152,,,
17.8,2.07683,12917.73,0.00156,,,
18,2.10023,13137.18,0.0016,,,
18.2,2.12354,13360.80,0.00164,,,
18.4,2.14694,13584.07,0.00167,,,
18.6,2.17009,13808.91,0.00172,,,
18.8,2.1935,14020.20,0.00175,,,
19,2.21675,14243.66,0.0018,,,
19.2,2.24026,14462.84,0.00185,,,
19.4,2.26371,14685.31,0.00189,,,
19.6,2.28681,14899.97,0.00195,,,
19.8,2.31027,15103.96,0.002,,,
20,2.33342,15314.24,0.00207,,,
20.2,2.35692,15514.83,0.00214,,,
20.4,2.38013,15712.73,0.00222,,,
20.6,2.40348,15889.82,0.0023,,,
20.8,2.42678,16050.65,0.0024,,,
21,2.45024,16200.47,0.00253,,,
21.2,2.47369,16330.38,0.00267,,,
21.4,2.4968,16439.62,0.00283,,,
21.6,2.5202,16520.79,0.00302,,,
21.8,2.54355,16587.09,0.00323,,,
22,2.56701,16638.20,0.00346,,,
22.2,2.59021,16673.52,0.0037,,,
22.4,2.61357,16680.11,0.00398,,,
22.6,2.63692,16644.59,0.0043,,,
22.8,2.66032,16538.25,0.00469,,,
23,2.68373,16429.92,0.00514,,,
23.2,2.70683,16389.57,0.00556,,,
23.4,2.73028,16359.17,0.00597,,,
23.6,2.75349,16356.65,0.00638,,,
23.8,2.77694,16378.44,0.00675,,,
24,2.80029,16402.42,0.0071,,,
24.2,2.8235,16400.02,0.00744,,,
24.4,2.84695,16390.99,0.00778,,,
24.6,2.87021,16390.24,0.0081,,,
24.8,2.89376,16400.60,0.0084,,,
25,2.91676,16405.96,0.00869,,,
25.2,2.94027,16404.81,0.00896,,,
25.4,2.96347,16415.75,0.00922,,,
25.6,2.98692,16438.55,0.00947,,,
25.8,3.01038,16473.95,0.00975,,,
26,3.03348,16489.97,0.01004,,,
26.2,3.05704,16497.50,0.01034,,,
26.4,3.08019,16502.96,0.01063,,,
26.6,3.10364,16505.07,0.0109,,,
26.8,3.1268,16508.71,0.01116,,,
27,3.15025,16511.61,0.01141,,,
27.2,3.17345,16517.76,0.01164,,,
27.4,3.19691,16532.26,0.01188,,,
27.6,3.22036,16551.78,0.01213,,,
27.8,3.24351,16568.63,0.01241,,,
28,3.26697,16580.75,0.01269,,,
28.2,3.29007,16592.59,0.013,,,
28.4,3.31363,16591.15,0.01331,,,
28.6,3.33683,16579.78,0.01366,,,
28.8,3.36018,16540.51,0.01404,,,
29,3.38349,16542.62,0.01441,,,
29.2,3.40684,16591.46,0.01474,,,
29.4,3.4304,16666.99,0.01503,,,
29.6,3.45345,16731.71,0.0153,,,
29.8,3.47695,16791.35,0.01555,,,
30,3.50016,16845.04,0.01579,,,
30.2,3.52361,16889.22,0.01602,,,
30.4,3.54691,16931.81,0.01626,,,
30.6,3.57017,16960.78,0.01648,,,
30.8,3.59357,16996.42,0.0167,,,
31,3.61692,17031.58,0.01692,,,
31.2,3.64038,17068.81,0.01713,,,
31.4,3.66348,17104.57,0.01735,,,
31.6,3.68683,17137.55,0.01757,,,
31.8,3.71009,17167.24,0.0178,,,
32,3.73354,17202.36,0.01802,,,
32.2,3.7569,17237.56,0.01825,,,
32.4,3.78015,17269.14,0.01846,,,
32.6,3.8035,17306.46,0.01869,,,
32.8,3.82686,17337.62,0.01891,,,
33,3.85036,17369.01,0.01914,,,
33.2,3.87351,17403.88,0.01938,,,
33.4,3.89682,17435.35,0.0196,,,
33.6,3.92012,17472.67,0.01983,,,
33.8,3.94348,17504.02,0.02006,,,
34,3.96708,17541.50,0.02029,,,
34.2,3.99018,17563.86,0.02053,,,
34.4,4.01359,17597.70,0.02076,,,
34.6,4.03679,17629.89,0.02099,,,
34.8,4.0604,17665.13,0.02122,,,
35,4.0835,17698.45,0.02146,,,
35.2,4.10685,17729.38,0.0217,,,
35.4,4.13021,17756.64,0.02194,,,
35.6,4.15361,17787.54,0.02217,,,
35.8,4.17701,17820.13,0.02241,,,
36,4.20022,17851.75,0.02265,,,
36.2,4.22362,17881.96,0.02288,,,
36.4,4.24682,17913.08,0.02312,,,
36.6,4.27033,17938.22,0.02336,,,
36.8,4.29353,17968.85,0.0236,,,
37,4.31683,17996.99,0.02384,,,
37.2,4.34024,18029.85,0.02408,,,
37.4,4.36359,18058.48,0.02432,,,
37.6,4.38705,18089.32,0.02457,,,
37.8,4.4102,18111.59,0.0248,,,
38,4.4335,18139.23,0.02505,,,
38.2,4.45681,18170.30,0.02529,,,
38.4,4.48021,18198.96,0.02553,,,
38.6,4.50361,18233.38,0.02577,,,
38.8,4.52682,18253.22,0.02601,,,
39,4.55027,18278.25,0.02626,,,
39.2,4.57363,18304.88,0.02651,,,
39.4,4.59708,18335.25,0.02674,,,
39.6,4.62023,18365.13,0.02699,,,
39.8,4.64359,18388.28,0.02723,,,
40,4.66684,18418.41,0.02748,,,
40.2,4.69019,18434.69,0.02772,,,
40.4,4.71355,18466.09,0.02797,,,
40.6,4.73685,18491.29,0.02821,,,
40.8,4.76026,18518.13,0.02846,,,
41,4.78356,18544.14,0.02871,,,
41.2,4.80696,18569.21,0.02895,,,
41.4,4.83012,18591.41,0.0292,,,
41.6,4.85352,18614.38,0.02944,,,
41.8,4.87687,18642.64,0.02969,,,
42,4.90028,18667.59,0.02994,,,
42.2,4.92363,18697.26,0.03019,,,
42.4,4.94684,18712.82,0.03044,,,
42.6,4.97029,18734.77,0.03068,,,
42.8,4.99354,18760.98,0.03093,,,
43,5.017,18785.66,0.03118,,,
43.2,5.04015,18813.60,0.03144,,,
43.4,5.06355,18833.05,0.03168,,,
43.6,5.08681,18852.93,0.03193,,,
43.8,5.11016,18876.42,0.03218,,,
44,5.13372,18902.92,0.03243,,,
44.2,5.15682,18925.88,0.03268,,,
44.4,5.18027,18947.34,0.03294,,,
44.6,5.20348,18964.69,0.0332,,,
44.8,5.22693,18988.02,0.03344,,,
45,5.25013,19013.96,0.0337,,,
45.2,5.27354,19033.64,0.03395,,,
45.4,5.29679,19057.78,0.0342,,,
45.6,5.32024,19077.52,0.03447,,,
45.8,5.34365,19094.97,0.03471,,,
46,5.36685,19116.76,0.03497,,,
46.2,5.39026,19137.83,0.03523,,,
46.4,5.41331,19160.06,0.03548,,,
46.6,5.43701,19183.17,0.03574,,,
46.8,5.46027,19209.21,0.03599,,,
47,5.48352,19217.55,0.03625,,,
47.2,5.50687,19238.98,0.0365,,,
47.4,5.53023,19260.31,0.03677,,,
47.6,5.55373,19281.86,0.03702,,,
47.8,5.57683,19304.03,0.03728,,,
48,5.60024,19322.29,0.03753,,,
48.2,5.62349,19340.97,0.0378,,,
48.4,5.6469,19355.92,0.03806,,,
48.6,5.6703,19379.31,0.03831,,,
48.8,5.69345,19395.07,0.03857,,,
49,5.71696,19417.40,0.03882,,,
49.2,5.74021,19437.89,0.03909,,,
49.4,5.76366,19455.97,0.03934,,,
49.6,5.78677,19468.28,0.03961,,,
49.8,5.81022,19486.37,0.03986,,,
50,5.83342,19506.55,0.04013,,,
50.2,5.85698,19525.55,0.04039,,,
50.4,5.88033,19548.71,0.04065,,,
50.6,5.90354,19563.99,0.04091,,,
50.8,5.92699,19575.88,0.04117,,,
51,5.95014,19592.82,0.04144,,,
51.2,5.9737,19612.04,0.04169,,,
51.4,5.99675,19632.15,0.04196,,,
51.6,6.02015,19647.15,0.04222,,,
51.8,6.04346,19666.06,0.04248,,,
52,6.06691,19679.55,0.04274,,,
52.2,6.09037,19695.89,0.04302,,,
52.4,6.11352,19713.07,0.04327,,,
52.6,6.13692,19729.04,0.04353,,,
52.8,6.16028,19750.42,0.0438,,,
53,6.18373,19767.55,0.04406,,,
53.2,6.20688,19781.59,0.04433,,,
53.4,6.23014,19789.41,0.0446,,,
53.6,6.25354,19809.06,0.04486,,,
53.8,6.2769,19823.23,0.04512,,,
54,6.3004,19843.16,0.04539,,,
54.2,6.32345,19858.20,0.04566,,,
54.4,6.34701,19872.86,0.04592,,,
54.6,6.37016,19882.24,0.04619,,,
54.8,6.39356,19898.35,0.04645,,,
55,6.41687,19917.82,0.04672,,,
55.2,6.44012,19930.37,0.04699,,,
55.4,6.46358,19948.77,0.04725,,,
55.6,6.48688,19961.21,0.04752,,,
55.8,6.51048,19973.82,0.04779,,,
56,6.53344,19987.39,0.04806,,,
56.2,6.55694,20002.40,0.04833,,,
56.4,6.58019,20019.62,0.0486,,,
56.6,6.6036,20034.54,0.04887,,,
56.8,6.62695,20051.11,0.04913,,,
57,6.6502,20053.80,0.04941,,,
57.2,6.67366,20070.28,0.04968,,,
57.4,6.69691,20084.56,0.04994,,,
57.6,6.72037,20100.41,0.05021,,,
57.8,6.74342,20117.19,0.05048,,,
58,6.76687,20126.30,0.05076,,,
58.2,6.79013,20134.56,0.05102,,,
58.4,6.81353,20150.32,0.0513,,,
58.6,6.83704,20166.80,0.05157,,,
58.8,6.86019,20178.41,0.05185,,,
59,6.88364,20192.68,0.05211,,,
59.2,6.9068,20205.25,0.05238,,,
59.4,6.93035,20216.79,0.05266,,,
59.6,6.9534,20225.27,0.05293,,,
59.8,6.97686,20236.37,0.0532,,,
60,7.00011,20253.86,0.05347,,,
60.2,7.02351,20263.83,0.05375,,,
60.4,7.04702,20283.08,0.05402,,,
60.6,7.07012,20288.67,0.0543,,,
60.8,7.09373,20297.94,0.05458,,,
61,7.11683,20311.73,0.05484,,,
61.2,7.14033,20325.35,0.05511,,,
61.4,7.16349,20340.42,0.05539,,,
61.6,7.18684,20349.27,0.05567,,,
61.8,7.21019,20362.47,0.05595,,,
62,7.2336,20366.76,0.05622,,,
62.2,7.257,20380.64,0.0565,,,
62.4,7.2802,20393.04,0.05677,,,
62.6,7.30351,20401.59,0.05705,,,
62.8,7.32676,20417.50,0.05732,,,
63,7.35027,20430.55,0.05761,,,
63.2,7.37352,20435.37,0.05788,,,
63.4,7.39682,20442.23,0.05816,,,
63.6,7.42013,20456.75,0.05844,,,
63.8,7.44358,20468.74,0.05872,,,
64,7.46708,20483.59,0.05899,,,
64.2,7.49019,20494.63,0.05927,,,
64.4,7.51354,20499.15,0.05955,,,
64.6,7.53679,20507.74,0.05982,,,
64.8,7.5602,20518.54,0.06011,,,
65,7.5837,20534.07,0.06038,,,
65.2,7.60681,20540.12,0.06067,,,
65.4,7.63031,20553.48,0.06094,,,
65.6,7.65351,20562.83,0.06123,,,
65.8,7.67712,20567.54,0.0615,,,
66,7.70007,20579.31,0.06178,,,
66.2,7.72358,20588.03,0.06207,,,
66.4,7.74683,20600.09,0.06236,,,
66.6,7.77028,20613.96,0.06263,,,
66.8,7.79364,20625.46,0.06292,,,
67,7.81684,20626.37,0.0632,,,
67.2,7.84029,20634.09,0.06349,,,
67.4,7.8635,20644.40,0.06376,,,
67.6,7.88715,20656.92,0.06405,,,
67.8,7.91005,20666.19,0.06432,,,
68,7.93356,20676.65,0.06462,,,
68.2,7.95681,20684.88,0.06489,,,
68.4,7.98027,20688.32,0.06518,,,
68.6,8.00367,20699.07,0.06546,,,
68.8,8.02682,20707.53,0.06575,,,
69,8.05023,20715.87,0.06603,,,
69.2,8.07353,20728.22,0.06632,,,
69.4,8.09698,20736.57,0.06659,,,
69.6,8.12019,20746.30,0.06688,,,
69.8,8.14349,20745.50,0.06716,,,
70,8.16694,20758.99,0.06745,,,
70.2,8.19035,20768.84,0.06774,,,
70.4,8.21375,20779.01,0.06803,,,
70.6,8.23686,20788.29,0.06831,,,
70.8,8.26031,20793.02,0.0686,,,
71,8.28346,20801.56,0.06889,,,
71.2,8.30692,20803.08,0.06917,,,
71.4,8.33017,20814.96,0.06946,,,
71.6,8.35347,20820.85,0.06975,,,
71.8,8.37688,20831.29,0.07003,,,
72,8.40028,20840.48,0.07032,,,
72.2,8.42369,20849.39,0.07061,,,
72.4,8.44679,20850.86,0.0709,,,
72.6,8.47029,20858.46,0.07118,,,
72.8,8.49355,20867.92,0.07147,,,
73,8.51685,20876.04,0.07176,,,
73.2,8.54025,20889.10,0.07205,,,
73.4,8.56341,20891.89,0.07234,,,
73.6,8.58701,20897.40,0.07263,,,
73.8,8.61016,20900.35,0.07291,,,
74,8.63377,20912.00,0.0732,,,
74.2,8.65677,20921.13,0.0735,,,
74.4,8.68028,20926.25,0.07379,,,
74.6,8.70348,20937.12,0.07408,,,
74.8,8.72683,20941.32,0.07437,,,
75,8.75034,20944.64,0.07466,,,
75.2,8.77354,20951.00,0.07495,,,
75.4,8.79694,20956.91,0.07524,,,
75.6,8.8201,20966.13,0.07553,,,
75.8,8.8437,20976.17,0.07583,,,
76,8.86676,20983.85,0.07612,,,
76.2,8.89026,20981.64,0.07641,,,
76.4,8.91341,20989.92,0.0767,,,
76.6,8.93692,20998.24,0.07699,,,
76.8,8.96027,21007.47,0.07729,,,
77,8.98347,21013.13,0.07758,,,
77.2,9.00693,21019.18,0.07788,,,
77.4,9.03003,21017.97,0.07816,,,
77.6,9.05369,21028.24,0.07847,,,
77.8,9.07679,21038.10,0.07876,,,
78,9.10014,21040.24,0.07905,,,
78.2,9.12355,21050.68,0.07934,,,
78.4,9.14685,21056.60,0.07964,,,
78.6,9.17045,21060.55,0.07993,,,
78.8,9.19356,21063.74,0.08023,,,
79,9.21696,21068.51,0.08052,,,
79.2,9.24017,21078.17,0.08081,,,
79.4,9.26362,21085.67,0.08111,,,
79.6,9.28687,21094.20,0.08141,,,
79.8,9.31013,21088.34,0.0817,,,
80,9.33353,21097.04,0.082,,,
80.2,9.35693,21105.01,0.0823,,,
80.4,9.38039,21113.23,0.08259,,,
80.6,9.40349,21119.25,0.08289,,,
80.8,9.42694,21123.65,0.08319,,,
81,9.4501,21123.22,0.08348,,,
81.2,9.4737,21130.26,0.08379,,,
81.4,9.49691,21139.87,0.08408,,,
81.6,9.52016,21142.71,0.08438,,,
81.8,9.54361,21151.20,0.08468,,,
82,9.56687,21155.40,0.08498,,,
82.2,9.59047,21155.62,0.08527,,,
82.4,9.61337,21160.97,0.08558,,,
82.6,9.63683,21164.84,0.08588,,,
82.8,9.66008,21174.03,0.08618,,,
83,9.68359,21180.48,0.08648,,,
83.2,9.70694,21187.48,0.08678,,,
83.4,9.73019,21184.45,0.08708,,,
83.6,9.7536,21190.48,0.08739,,,
83.8,9.777,21198.76,0.08768,,,
84,9.8004,21204.68,0.08799,,,
84.2,9.82346,21211.86,0.08828,,,
84.4,9.84686,21215.24,0.08859,,,
84.6,9.87006,21215.57,0.08889,,,
84.8,9.89367,21216.41,0.0892,,,
85,9.91702,21224.97,0.08949,,,
85.2,9.94018,21230.72,0.0898,,,
85.4,9.96363,21233.86,0.0901,,,
85.6,9.98683,21242.14,0.0904,,,
85.8,10.01034,21246.74,0.09071,,,
86,10.03349,21246.28,0.09101,,,
86.2,10.05679,21247.29,0.09132,,,
86.4,10.0802,21255.16,0.09161,,,
86.6,10.1036,21260.41,0.09192,,,
86.8,10.12716,21269.52,0.09222,,,
87,10.15016,21272.63,0.09253,,,
87.2,10.17366,21273.80,0.09284,,,
87.4,10.19687,21274.04,0.09315,,,
87.6,10.22032,21278.89,0.09345,,,
87.8,10.24357,21289.69,0.09376,,,
88,10.26688,21288.31,0.09407,,,
88.2,10.29023,21295.62,0.09438,,,
88.4,10.31364,21300.75,0.09468,,,
88.6,10.33704,21297.95,0.09499,,,
88.8,10.36019,21304.48,0.09529,,,
89,10.38365,21306.23,0.0956,,,
89.2,10.4068,21312.90,0.09591,,,
89.4,10.43025,21317.32,0.09622,,,
89.6,10.45356,21326.49,0.09653,,,
89.8,10.47691,21324.27,0.09683,,,
90,10.50031,21323.83,0.09715,,,
90.2,10.52352,21328.30,0.09746,,,
90.4,10.54707,21335.69,0.09777,,,
90.6,10.57008,21340.31,0.09808,,,
90.8,10.59358,21343.10,0.09839,,,
91,10.61668,21347.01,0.0987,,,
91.2,10.64024,21343.01,0.09901,,,
91.4,10.66364,21352.57,0.09933,,,
91.6,10.68684,21352.44,0.09963,,,
91.8,10.7103,21358.05,0.09995,,,
92,10.7335,21365.28,0.10026,,,
92.2,10.75706,21370.21,0.10057,,,
92.4,10.78016,21370.92,0.10088,,,
92.6,10.80356,21367.39,0.10121,,,
92.8,10.82682,21375.46,0.10151,,,
93,10.85022,21378.90,0.10183,,,
93.2,10.87362,21384.08,0.10213,,,
93.4,10.89693,21389.17,0.10246,,,
93.6,10.92023,21384.58,0.10277,,,
93.8,10.94349,21388.16,0.10308,,,
94,10.96694,21392.44,0.10339,,,
94.2,10.99014,21399.02,0.10371,,,
94.4,11.01345,21399.14,0.10403,,,
94.6,11.0367,21406.42,0.10434,,,
94.8,11.0603,21402.69,0.10466,,,
95,11.08366,21408.98,0.10498,,,
95.2,11.10691,21410.94,0.10529,,,
95.4,11.13021,21412.79,0.10561,,,
95.6,11.15347,21419.97,0.10592,,,
95.8,11.17692,21422.28,0.10625,,,
96,11.20033,21425.55,0.10656,,,
96.2,11.22348,21419.20,0.10688,,,
96.4,11.24693,21427.31,0.1072,,,
96.6,11.27019,21429.86,0.10752,,,
96.8,11.29384,21438.15,0.10783,,,
97,11.31674,21439.43,0.10816,,,
97.2,11.3403,21438.57,0.10847,,,
97.4,11.36355,21438.15,0.10879,,,
97.6,11.38701,21443.90,0.10911,,,
97.8,11.41021,21448.70,0.10943,,,
98,11.43351,21450.07,0.10975,,,
98.2,11.45697,21455.06,0.11007,,,
98.4,11.48022,21455.23,0.11039,,,
98.6,11.50377,21455.25,0.11072,,,
98.8,11.52673,21456.53,0.11103,,,
99,11.55023,21458.24,0.11136,,,
99.2,11.57343,21464.34,0.11168,,,
99.4,11.59699,21467.18,0.11201,,,
99.6,11.62019,21472.10,0.11232,,,
99.8,11.64345,21470.86,0.11265,,,
100,11.6669,21466.80,0.11297,,,
100.2,11.6902,21471.35,0.1133,,,
100.4,11.71366,21474.18,0.11362,,,
100.6,11.73686,21483.09,0.11394,,,
100.8,11.76016,21480.95,0.11427,,,
101,11.78362,21488.51,0.11459,,,
101.2,11.80697,21486.16,0.11492,,,
101.4,11.83038,21485.58,0.11524,,,
101.6,11.85348,21487.82,0.11556,,,
101.8,11.87698,21488.96,0.11589,,,
102,11.90019,21494.40,0.11622,,,
102.2,11.92359,21496.63,0.11655,,,
102.4,11.94679,21501.78,0.11687,,,
102.6,11.9702,21492.59,0.1172,,,
102.8,11.99355,21496.88,0.11752,,,
103,12.01691,21498.70,0.11785,,,
103.2,12.04036,21504.85,0.11818,,,
103.4,12.06346,21507.26,0.11851,,,
103.6,12.08692,21509.12,0.11884,,,
103.8,12.11022,21510.48,0.11916,,,
104,12.13367,21507.18,0.1195,,,
104.2,12.15683,21511.86,0.11982,,,
104.4,12.18013,21510.82,0.12015,,,
104.6,12.20363,21516.54,0.12048,,,
104.8,12.22684,21516.93,0.12082,,,
105,12.25044,21524.97,0.12114,,,
105.2,12.27349,21524.81,0.12148,,,
105.4,12.2969,21519.43,0.12181,,,
105.6,12.3202,21521.40,0.12215,,,
105.8,12.34351,21522.87,0.12248,,,
106,12.36691,21529.50,0.12281,,,
106.2,12.39011,21528.22,0.12315,,,
106.4,12.41357,21532.36,0.12348,,,
106.6,12.43692,21534.70,0.12381,,,
106.8,12.46038,21529.15,0.12415,,,
107,12.48348,21532.83,0.12449,,,
107.2,12.50688,21533.04,0.12481,,,
107.4,12.53004,21536.65,0.12515,,,
107.6,12.55364,21539.83,0.12549,,,
107.8,12.57689,21544.53,0.12583,,,
108,12.6002,21541.17,0.12617,,,
108.2,12.6236,21537.49,0.12651,,,
108.4,12.64675,21538.30,0.12684,,,
108.6,12.67041,21545.87,0.12718,,,
108.8,12.69341,21548.95,0.12751,,,
109,12.71687,21547.64,0.12786,,,
109.2,12.74017,21552.66,0.1282,,,
109.4,12.76357,21545.41,0.12853,,,
109.6,12.78703,21548.91,0.12888,,,
109.8,12.81028,21551.45,0.12921,,,
110,12.83363,21552.03,0.12955,,,
110.2,12.85694,21557.05,0.12989,,,
110.4,12.88029,21558.16,0.13024,,,
110.6,12.90355,21558.60,0.13058,,,
110.8,12.92675,21550.63,0.13091,,,
111,12.95015,21557.54,0.13126,,,
111.2,12.97356,21559.58,0.1316,,,
111.4,12.99696,21562.61,0.13194,,,
111.6,13.02016,21564.00,0.13229,,,
111.8,13.04357,21559.36,0.13263,,,
112,13.06682,21560.82,0.13298,,,
112.2,13.09038,21563.15,0.13332,,,
112.4,13.11348,21567.61,0.13367,,,
112.6,13.13683,21565.92,0.13402,,,
112.8,13.16024,21570.46,0.13436,,,
113,13.18349,21566.84,0.13471,,,
113.2,13.20714,21565.43,0.13506,,,
113.4,13.2301,21566.54,0.1354,,,
113.6,13.25355,21567.26,0.13575,,,
113.8,13.27675,21569.99,0.13609,,,
114,13.30031,21574.34,0.13645,,,
114.2,13.32351,21576.04,0.13679,,,
114.4,13.34687,21568.43,0.13714,,,
114.6,13.37027,21569.69,0.13749,,,
114.8,13.39367,21573.61,0.13784,,,
115,13.41703,21576.05,0.13819,,,
115.2,13.44013,21579.19,0.13854,,,
115.4,13.46353,21577.23,0.13889,,,
115.6,13.48679,21575.86,0.13925,,,
115.8,13.51034,21572.81,0.1396,,,
116,13.53365,21577.65,0.13996,,,
116.2,13.5568,21575.51,0.14029,,,
116.4,13.5803,21579.37,0.14065,,,
116.6,13.60366,21583.08,0.14101,,,
116.8,13.62696,21577.47,0.14136,,,
117,13.65016,21577.61,0.14172,,,
117.2,13.67347,21575.46,0.14207,,,
117.4,13.69682,21581.03,0.14242,,,
117.6,13.72023,21581.06,0.14279,,,
117.8,13.74373,21587.13,0.14313,,,
118,13.76683,21582.14,0.1435,,,
118.2,13.79039,21577.22,0.14385,,,
118.4,13.81354,21579.78,0.14421,,,
118.6,13.83709,21582.44,0.14457,,,
118.8,13.86015,21585.93,0.14493,,,
119,13.88355,21583.54,0.14529,,,
119.2,13.90685,21586.86,0.14565,,,
119.4,13.93026,21579.06,0.146,,,
119.6,13.95366,21581.19,0.14637,,,
119.8,13.97687,21582.45,0.14673,,,
120,14.00032,21581.79,0.1471,,,
120.2,14.02347,21583.70,0.14746,,,
120.4,14.04698,21586.90,0.14781,,,
120.6,14.07018,21582.72,0.14818,,,
120.8,14.09353,21579.63,0.14854,,,
121,14.11694,21582.49,0.14891,,,
121.2,14.14024,21583.32,0.14927,,,
121.4,14.1637,21586.74,0.14963,,,
121.6,14.1868,21587.54,0.15,,,
121.8,14.21025,21580.58,0.15037,,,
122,14.23345,21581.39,0.15073,,,
122.2,14.25691,21579.97,0.1511,,,
122.4,14.28021,21585.81,0.15148,,,
122.6,14.30352,21581.25,0.15184,,,
122.8,14.32692,21584.70,0.15221,,,
123,14.35017,21587.00,0.15258,,,
123.2,14.37378,21581.18,0.15295,,,
123.4,14.39678,21581.79,0.15332,,,
123.6,14.42029,21579.61,0.15369,,,
123.8,14.44344,21584.23,0.15406,,,
124,14.46694,21585.19,0.15443,,,
124.2,14.49025,21587.30,0.1548,,,
124.4,14.51355,21582.94,0.15518,,,
124.6,14.5369,21575.85,0.15555,,,
124.8,14.56021,21580.48,0.15592,,,
125,14.58366,21581.39,0.1563,,,
125.2,14.60676,21583.09,0.15667,,,
125.4,14.63017,21581.72,0.15705,,,
125.6,14.65332,21580.71,0.15743,,,
125.8,14.67698,21575.83,0.1578,,,
126,14.70033,21580.54,0.15818,,,
126.2,14.72343,21577.80,0.15856,,,
126.4,14.74699,21579.48,0.15894,,,
126.6,14.77014,21581.46,0.15932,,,
126.8,14.7937,21577.21,0.1597,,,
127,14.8169,21576.05,0.16007,,,
127.2,14.84015,21572.37,0.16045,,,
127.4,14.86361,21576.55,0.16084,,,
127.6,14.88691,21576.54,0.16121,,,
127.8,14.91047,21581.07,0.1616,,,
128,14.93342,21577.01,0.16198,,,
128.2,14.95697,21569.63,0.16236,,,
128.4,14.98022,21570.93,0.16275,,,
128.6,15.00363,21573.68,0.16314,,,
128.8,15.02683,21574.37,0.16351,,,
129,15.05019,21572.42,0.16391,,,
129.2,15.07354,21574.24,0.16429,,,
129.4,15.09699,21567.70,0.16467,,,
129.6,15.12045,21568.13,0.16507,,,
129.8,15.14345,21566.65,0.16546,,,
130,15.16695,21566.41,0.16584,,,
130.2,15.19016,21568.90,0.16623,,,
130.4,15.21361,21569.75,0.16663,,,
130.6,15.23687,21567.86,0.167,,,
130.8,15.26017,21558.71,0.1674,,,
131,15.28357,21560.14,0.1678,,,
131.2,15.30688,21560.12,0.16818,,,
131.4,15.33038,21560.62,0.16858,,,
131.6,15.35348,21563.38,0.16898,,,
131.8,15.37689,21560.79,0.16936,,,
132,15.40029,21561.47,0.16976,,,
132.2,15.42359,21553.24,0.17016,,,
132.4,15.447,21556.39,0.17054,,,
132.6,15.47015,21552.48,0.17094,,,
132.8,15.49361,21551.74,0.17134,,,
133,15.51691,21554.17,0.17174,,,
133.2,15.54031,21554.17,0.17213,,,
133.4,15.56342,21554.74,0.17254,,,
133.6,15.58692,21543.10,0.17294,,,
133.8,15.61017,21544.87,0.17333,,,
134,15.63358,21543.74,0.17374,,,
134.2,15.65698,21547.21,0.17414,,,
134.4,15.68009,21543.89,0.17453,,,
134.6,15.70364,21546.43,0.17495,,,
134.8,15.72694,21541.51,0.17535,,,
135,15.75035,21535.99,0.17575,,,
135.2,15.77345,21538.80,0.17616,,,
135.4,15.79685,21533.77,0.17656,,,
135.6,15.82021,21536.11,0.17697,,,
135.8,15.84356,21535.56,0.17738,,,
136,15.86712,21539.04,0.17779,,,
136.2,15.89012,21529.57,0.1782,,,
136.4,15.91367,21524.60,0.1786,,,
136.6,15.93683,21524.80,0.17902,,,
136.8,15.96023,21524.03,0.17943,,,
137,15.98358,21527.23,0.17983,,,
137.2,16.00679,21521.87,0.18024,,,
137.4,16.03024,21523.52,0.18066,,,
137.6,16.05349,21521.36,0.18107,,,
137.8,16.0771,21517.43,0.18148,,,
138,16.10015,21512.51,0.1819,,,
138.2,16.12361,21510.62,0.18231,,,
138.4,16.14676,21510.86,0.18273,,,
138.6,16.17031,21509.87,0.18315,,,
138.8,16.19347,21510.35,0.18356,,,
139,16.21687,21507.23,0.18398,,,
139.2,16.24017,21504.80,0.1844,,,
139.4,16.26348,21494.96,0.18482,,,
139.6,16.28713,21498.82,0.18524,,,
139.8,16.31018,21497.14,0.18566,,,
140,16.33359,21491.95,0.18608,,,
140.2,16.35679,21494.05,0.1865,,,
140.4,16.3802,21492.75,0.18692,,,
140.6,16.40365,21493.29,0.18735,,,
140.8,16.4269,21484.87,0.18777,,,
141,16.45031,21479.57,0.18819,,,
141.2,16.47356,21479.17,0.18862,,,
141.4,16.49707,21478.59,0.18904,,,
141.6,16.52027,21480.71,0.18947,,,
141.8,16.54347,21473.38,0.1899,,,
142,16.56683,21473.54,0.19033,,,
142.2,16.59018,21463.86,0.19075,,,
142.4,16.61363,21463.17,0.19119,,,
142.6,16.63679,21458.69,0.19161,,,
142.8,16.66024,21458.54,0.19204,,,
143,16.68349,21455.70,0.19248,,,
143.2,16.70705,21458.05,0.19291,,,
143.4,16.73015,21454.53,0.19334,,,
143.6,16.75351,21440.63,0.19378,,,
143.8,16.77681,21441.30,0.19421,,,
144,16.80016,21437.32,0.19464,,,
144.2,16.82382,21439.95,0.19508,,,
144.4,16.84682,21434.87,0.19552,,,
144.6,16.87028,21431.77,0.19595,,,
144.8,16.89343,21423.13,0.19639,,,
145,16.91703,21419.28,0.19683,,,
145.2,16.94013,21417.95,0.19727,,,
145.4,16.96359,21414.21,0.1977,,,
145.6,16.98684,21411.27,0.19816,,,
145.8,17.0103,21411.84,0.19859,,,
146,17.0337,21406.75,0.19904,,,
146.2,17.05685,21398.12,0.19947,,,
146.4,17.08026,21389.45,0.19992,,,
146.6,17.10346,21388.21,0.20037,,,
146.8,17.12701,21383.91,0.20081,,,
147,17.15022,21382.54,0.20126,,,
147.2,17.17352,21376.98,0.2017,,,
147.4,17.19687,21373.10,0.20215,,,
147.6,17.22028,21364.20,0.2026,,,
147.8,17.24373,21357.04,0.20304,,,
148,17.26684,21355.63,0.20349,,,
148.2,17.29019,21347.93,0.20394,,,
148.4,17.31344,21347.03,0.20439,,,
148.6,17.33695,21341.82,0.20484,,,
148.8,17.3603,21337.71,0.20528,,,
149,17.3835,21322.00,0.20574,,,
149.2,17.40706,21320.13,0.20618,,,
149.4,17.43021,21314.57,0.20663,,,
149.6,17.45382,21310.85,0.20709,,,
149.8,17.47682,21307.37,0.20754,,,
150,17.50027,21297.91,0.20799,,,
150.2,17.52348,21289.66,0.20845,,,
150.4,17.54693,21277.87,0.2089,,,
150.6,17.57034,21273.61,0.20936,,,
150.8,17.59349,21266.68,0.20982,,,
151,17.61699,21259.08,0.21027,,,
151.2,17.6402,21252.97,0.21073,,,
151.4,17.6637,21246.92,0.21118,,,
151.6,17.6868,21238.19,0.21165,,,
151.8,17.71021,21222.13,0.21211,,,
152,17.73351,21215.83,0.21256,,,
152.2,17.75691,21208.70,0.21302,,,
152.4,17.78037,21203.15,0.21348,,,
152.6,17.80342,21193.24,0.21394,,,
152.8,17.82697,21182.38,0.21441,,,
153,17.85013,21166.14,0.21486,,,
153.2,17.87368,21158.20,0.21533,,,
153.4,17.89679,21152.83,0.2158,,,
153.6,17.92019,21139.18,0.21625,,,
153.8,17.94354,21131.47,0.21671,,,
154,17.96685,21119.87,0.21718,,,
154.2,17.99045,21103.21,0.21765,,,
154.4,18.01345,21092.69,0.21811,,,
154.6,18.03701,21079.69,0.21858,,,
154.8,18.06006,21070.14,0.21904,,,
155,18.08362,21059.63,0.21951,,,
155.2,18.10682,21049.04,0.21997,,,
155.4,18.13027,21031.34,0.22044,,,
155.6,18.15353,21011.49,0.2209,,,
155.8,18.17688,20999.07,0.22137,,,
156,18.20033,20986.92,0.22184,,,
156.2,18.22349,20974.19,0.22232,,,
156.4,18.24694,20958.20,0.22278,,,
156.6,18.26999,20944.93,0.22325,,,
156.8,18.2937,20923.39,0.22371,,,
157,18.31685,20909.50,0.22419,,,
157.2,18.34016,20890.18,0.22466,,,
157.4,18.36361,20875.59,0.22512,,,
157.6,18.38691,20859.62,0.2256,,,
157.8,18.41037,20841.72,0.22605,,,
158,18.43357,20828.50,0.22651,,,
158.2,18.45688,20802.92,0.22699,,,
158.4,18.48013,20781.85,0.22746,,,
158.6,18.50353,20763.06,0.22792,,,
158.8,18.52699,20747.46,0.2284,,,
159,18.55014,20726.03,0.22887,,,
159.2,18.57359,20706.96,0.22934,,,
159.4,18.59695,20688.18,0.22982,,,
159.6,18.6203,20667.13,0.23029,,,
159.8,18.64345,20640.27,0.23076,,,
160,18.66686,20615.56,0.23124,,,
160.2,18.69011,20594.99,0.23171,,,
160.4,18.71367,20571.32,0.23219,,,
160.6,18.73712,20552.85,0.23266,,,
160.8,18.76012,20527.58,0.23314,,,
161,18.78363,20501.54,0.23361,,,
161.2,18.80683,20472.62,0.23409,,,
161.4,18.83039,20445.41,0.23457,,,
161.6,18.85344,20421.92,0.23505,,,
161.8,18.87684,20394.13,0.23552,,,
162,18.9002,20367.48,0.236,,,
162.2,18.92355,20341.89,0.23647,,,
162.4,18.94705,20312.93,0.23695,,,
162.6,18.97021,20279.20,0.23743,,,
162.8,18.99356,20247.19,0.23791,,,
163,19.01691,20220.69,0.23839,,,
163.2,19.04032,20189.35,0.23887,,,
163.4,19.06357,20161.39,0.23936,,,
163.6,19.08683,20127.41,0.23984,,,
163.8,19.11023,20093.00,0.24031,,,
164,19.13363,20053.75,0.2408,,,
164.2,19.15709,20020.00,0.24129,,,
164.4,19.18014,19988.17,0.24176,,,
164.6,19.20359,19950.26,0.24225,,,
164.8,19.22685,19918.39,0.24273,,,
165,19.25025,19878.28,0.24323,,,
165.2,19.27361,19844.06,0.24371,,,
165.4,19.29686,19796.18,0.2442,,,
165.6,19.32026,19760.03,0.24468,,,
165.8,19.34357,19720.52,0.24517,,,
166,19.36707,19683.25,0.24565,,,
166.2,19.39012,19644.11,0.24615,,,
166.4,19.41358,19600.46,0.24664,,,
166.6,19.43688,19561.65,0.24713,,,
166.8,19.46024,19512.98,0.24761,,,
167,19.48369,19471.07,0.2481,,,
167.2,19.50684,19422.70,0.2486,,,
167.4,19.53034,19379.00,0.24909,,,
167.6,19.55355,19333.71,0.24959,,,
167.8,19.57695,19285.88,0.25008,,,
168,19.60016,19240.67,0.25057,,,
168.2,19.62356,19186.77,0.25107,,,
168.4,19.64681,19132.11,0.25156,,,
168.6,19.67022,19076.93,0.25207,,,
168.8,19.69367,19026.38,0.25258,,,
169,19.71687,18971.23,0.25308,,,
169.2,19.74033,18913.82,0.25358,,,
169.4,19.76348,18855.49,0.25409,,,
169.6,19.78704,18796.26,0.2546,,,
169.8,19.81009,18735.96,0.25511,,,
170,19.83354,18664.90,0.25562,,,
170.2,19.85685,18603.64,0.25614,,,
170.4,19.8802,18531.89,0.25665,,,
170.6,19.90376,18461.82,0.25719,,,
170.8,19.92686,18381.20,0.25773,,,
171,19.95031,18291.60,0.25827,,,
171.2,19.97347,18203.36,0.25882,,,
171.4,19.99697,18102.96,0.25937,,,
171.6,20.02028,17993.89,0.25994,,,
171.8,20.04358,17845.74,0.26054,,,
172,20.06693,17667.89,0.26117,,,
172.2,20.09033,17416.83,0.26187,,,
172.4,20.11389,16852.43,0.26281,,,
172.6,20.13694,16197.54,0.26385,,,
172.8,20.1603,15702.68,0.26475,,,
173,20.1835,15191.10,0.2657,,,
173.2,20.20695,14807.11,0.26654,,,
173.4,20.23031,14378.14,0.26741,,,
173.6,20.25361,13786.50,0.26844,,,
173.8,20.27706,12979.10,0.26968,,,
174,20.30057,11711.12,0.27135,,,
174.2,20.32367,-506.61,0.28975,,,
174.4,20.34677,-510.68,0.29022,,,
174.6,20.37018,-510.48,0.2907,,,
174.8,20.39348,-510.27,0.29115,,,
175,20.41684,-509.90,0.29164,,,
175.2,20.44044,-509.53,0.29209,,,
175.4,20.46349,-509.20,0.29257,,,
175.6,20.487,-509.08,0.29301,,,
175.8,20.5101,-509.26,0.29349,,,
176,20.5337,-509.17,0.29394,,,
176.2,20.55686,-508.96,0.29442,,,
176.4,20.58021,-508.69,0.29487,,,
176.6,20.60352,-508.44,0.29535,,,
176.8,20.62687,-508.26,0.29581,,,
177,20.65037,-508.02,0.29627,,,
177.2,20.67348,-508.45,0.29674,,,
177.4,20.69698,-508.38,0.29719,,,
177.551,20.71451,-507.94,0.29755,,,